Workbook

Sheet Macro
A1: Evaluation of the Data, based on LCA methode
A3: List of Methods: | C3: Results:
A4: IPCC 2021 | climate change | global warming potential (GWP100)
A5: ReCiPe 2016 v1.03, endpoint (E) | ecosystem quality | acidification: terrestrial | K5: Relative Comparison
A6: ReCiPe 2016 v1.03, endpoint (E) | ecosystem quality | climate change: freshwater ecosystems | D6: Merck Synthesis Route | E6: Suggested Route | G6: Methode | H6: Merck Synthesis Route | I6: Suggested Route | L6: Merck Synthesis Route | M6: Suggested Route
A7: ReCiPe 2016 v1.03, endpoint (E) | ecosystem quality | climate change: terrestrial ecosystems | C7: LCI Category | D7: Letermovir | E7: Letermovir | F7: unit | H7: Letermovir Merck | I7: Letermovir Carreira | J7: unit | K7: Methode | L7: Letermovir Merck | M7: Letermovir Careirra
A8: ReCiPe 2016 v1.03, endpoint (E) | ecosystem quality | ecotoxicity: freshwater | C8: =A33 -> ReCiPe 2016 v1.03, endpoint (E) | total: natural resources | natural resources | D8: ='2.1. Merck LCA FU'!F108 -> 4.3951194 | E8: ='1.1 LCA This Work FU'!H107 -> 0 | G8: IPCC 2021 | climate change | global warming potential (GWP100) | H8: 0 | I8: 0 | J8: kg CO2-Eq | K8: IPCC 2013 | climate change | global warming potential (GWP100) | L8: =H8/SUM(H8:I8) -> #DIV/0! | M8: =I8/SUM(H8:I8) -> #DIV/0!
A9: ReCiPe 2016 v1.03, endpoint (E) | ecosystem quality | ecotoxicity: marine | G9: ReCiPe 2016 v1.03, endpoint (E) | ecosystem quality | acidification: terrestrial | H9: 0 | I9: 0 | J9: species.yr | K9: ReCiPe 2016 v1.03, endpoint (E) | ecosystem quality | acidification: terrestrial | L9: =H9/SUM(H9:I9) -> #DIV/0! | M9: =I9/SUM(H9:I9) -> #DIV/0!
A10: ReCiPe 2016 v1.03, endpoint (E) | ecosystem quality | ecotoxicity: terrestrial | G10: ReCiPe 2016 v1.03, endpoint (E) | ecosystem quality | climate change: freshwater ecosystems | H10: 0 | I10: 0 | J10: species.yr | K10: ReCiPe 2016 v1.03, endpoint (E) | ecosystem quality | climate change: freshwater ecosystems | L10: =H10/SUM(H10:I10) -> #DIV/0! | M10: =I10/SUM(H10:I10) -> #DIV/0!
A11: ReCiPe 2016 v1.03, endpoint (E) | ecosystem quality | eutrophication: freshwater | G11: ReCiPe 2016 v1.03, endpoint (E) | ecosystem quality | climate change: terrestrial ecosystems | H11: 0 | I11: 0 | J11: species.yr | K11: ReCiPe 2016 v1.03, endpoint (E) | ecosystem quality | climate change: terrestrial ecosystems | L11: =H11/SUM(H11:I11) -> #DIV/0! | M11: =I11/SUM(H11:I11) -> #DIV/0!
A12: ReCiPe 2016 v1.03, endpoint (E) | ecosystem quality | eutrophication: marine | G12: ReCiPe 2016 v1.03, endpoint (E) | ecosystem quality | ecotoxicity: freshwater | H12: 0 | I12: 0 | J12: species.yr | K12: ReCiPe 2016 v1.03, endpoint (E) | ecosystem quality | ecotoxicity: freshwater | L12: =H12/SUM(H12:I12) -> #DIV/0! | M12: =I12/SUM(H12:I12) -> #DIV/0!
A13: ReCiPe 2016 v1.03, endpoint (E) | ecosystem quality | land use | G13: ReCiPe 2016 v1.03, endpoint (E) | ecosystem quality | ecotoxicity: marine | H13: 0 | I13: 0 | J13: species.yr | K13: ReCiPe 2016 v1.03, endpoint (E) | ecosystem quality | ecotoxicity: marine | L13: =H13/SUM(H13:I13) -> #DIV/0! | M13: =I13/SUM(H13:I13) -> #DIV/0!
A14: ReCiPe 2016 v1.03, endpoint (E) | ecosystem quality | photochemical oxidant formation: terrestrial ecosystems | G14: ReCiPe 2016 v1.03, endpoint (E) | ecosystem quality | ecotoxicity: terrestrial | H14: 0 | I14: 0 | J14: species.yr | K14: ReCiPe 2016 v1.03, endpoint (E) | ecosystem quality | ecotoxicity: terrestrial | L14: =H14/SUM(H14:I14) -> #DIV/0! | M14: =I14/SUM(H14:I14) -> #DIV/0!
A15: ReCiPe 2016 v1.03, endpoint (E) | ecosystem quality | water use: aquatic ecosystems | C15: Recovery Rate Catalyst | D15: 0.5 | G15: ReCiPe 2016 v1.03, endpoint (E) | ecosystem quality | eutrophication: freshwater | H15: 0 | I15: 0 | J15: species.yr | K15: ReCiPe 2016 v1.03, endpoint (E) | ecosystem quality | eutrophication: freshwater | L15: =H15/SUM(H15:I15) -> #DIV/0! | M15: =I15/SUM(H15:I15) -> #DIV/0!
A16: ReCiPe 2016 v1.03, endpoint (E) | ecosystem quality | water use: terrestrial ecosystems | G16: ReCiPe 2016 v1.03, endpoint (E) | ecosystem quality | eutrophication: marine | H16: 0 | I16: 0 | J16: species.yr | K16: ReCiPe 2016 v1.03, endpoint (E) | ecosystem quality | eutrophication: marine | L16: =H16/SUM(H16:I16) -> #DIV/0! | M16: =I16/SUM(H16:I16) -> #DIV/0!
A17: ReCiPe 2016 v1.03, endpoint (E) | human health | climate change: human health | C17: Recovery Rate Catalyst (IDPi-1), pleae adjust in „B.1. Chiral Cat This Work“ | G17: ReCiPe 2016 v1.03, endpoint (E) | ecosystem quality | land use | H17: 0 | I17: 0 | J17: species.yr | K17: ReCiPe 2016 v1.03, endpoint (E) | ecosystem quality | land use | L17: =H17/SUM(H17:I17) -> #DIV/0! | M17: =I17/SUM(H17:I17) -> #DIV/0!
A18: ReCiPe 2016 v1.03, endpoint (E) | human health | human toxicity: carcinogenic | G18: ReCiPe 2016 v1.03, endpoint (E) | ecosystem quality | photochemical oxidant formation: terrestrial ecosystems | H18: 0 | I18: 0 | J18: species.yr | K18: ReCiPe 2016 v1.03, endpoint (E) | ecosystem quality | photochemical oxidant formation: terrestrial ecosystems | L18: =H18/SUM(H18:I18) -> #DIV/0! | M18: =I18/SUM(H18:I18) -> #DIV/0!
A19: ReCiPe 2016 v1.03, endpoint (E) | human health | human toxicity: non-carcinogenic | G19: ReCiPe 2016 v1.03, endpoint (E) | ecosystem quality | water use: aquatic ecosystems | H19: 0 | I19: 0 | J19: species.yr | K19: ReCiPe 2016 v1.03, endpoint (E) | ecosystem quality | water use: aquatic ecosystems | L19: =H19/SUM(H19:I19) -> #DIV/0! | M19: =I19/SUM(H19:I19) -> #DIV/0!
A20: ReCiPe 2016 v1.03, endpoint (E) | human health | ionising radiation | G20: ReCiPe 2016 v1.03, endpoint (E) | ecosystem quality | water use: terrestrial ecosystems | H20: 0 | I20: 0 | J20: species.yr | K20: ReCiPe 2016 v1.03, endpoint (E) | ecosystem quality | water use: terrestrial ecosystems | L20: =H20/SUM(H20:I20) -> #DIV/0! | M20: =I20/SUM(H20:I20) -> #DIV/0!
A21: ReCiPe 2016 v1.03, endpoint (E) | human health | ozone depletion | G21: ReCiPe 2016 v1.03, endpoint (E) | human health | climate change: human health | H21: 0 | I21: 0 | J21: DALYs | K21: ReCiPe 2016 v1.03, endpoint (E) | human health | climate change: human health | L21: =H21/SUM(H21:I21) -> #DIV/0! | M21: =I21/SUM(H21:I21) -> #DIV/0!
A22: ReCiPe 2016 v1.03, endpoint (E) | human health | particulate matter formation | G22: ReCiPe 2016 v1.03, endpoint (E) | human health | human toxicity: carcinogenic | H22: 0 | I22: 0 | J22: DALYs | K22: ReCiPe 2016 v1.03, endpoint (E) | human health | human toxicity: carcinogenic | L22: =H22/SUM(H22:I22) -> #DIV/0! | M22: =I22/SUM(H22:I22) -> #DIV/0!
A23: ReCiPe 2016 v1.03, endpoint (E) | human health | photochemical oxidant formation: human health | G23: ReCiPe 2016 v1.03, endpoint (E) | human health | human toxicity: non-carcinogenic | H23: 0 | I23: 0 | J23: DALYs | K23: ReCiPe 2016 v1.03, endpoint (E) | human health | human toxicity: non-carcinogenic | L23: =H23/SUM(H23:I23) -> #DIV/0! | M23: =I23/SUM(H23:I23) -> #DIV/0!
A24: ReCiPe 2016 v1.03, endpoint (E) | human health | water use: human health | G24: ReCiPe 2016 v1.03, endpoint (E) | human health | ionising radiation | H24: 0 | I24: 0 | J24: DALYs | K24: ReCiPe 2016 v1.03, endpoint (E) | human health | ionising radiation | L24: =H24/SUM(H24:I24) -> #DIV/0! | M24: =I24/SUM(H24:I24) -> #DIV/0!
A25: ReCiPe 2016 v1.03, endpoint (E) | natural resources | energy resources: non-renewable, fossil | G25: ReCiPe 2016 v1.03, endpoint (E) | human health | ozone depletion | H25: 0 | I25: 0 | J25: DALYs | K25: ReCiPe 2016 v1.03, endpoint (E) | human health | ozone depletion | L25: =H25/SUM(H25:I25) -> #DIV/0! | M25: =I25/SUM(H25:I25) -> #DIV/0!
A26: ReCiPe 2016 v1.03, endpoint (E) | natural resources | material resources: metals/minerals | G26: ReCiPe 2016 v1.03, endpoint (E) | human health | particulate matter formation | H26: 0 | I26: 0 | J26: DALYs | K26: ReCiPe 2016 v1.03, endpoint (E) | human health | particulate matter formation | L26: =H26/SUM(H26:I26) -> #DIV/0! | M26: =I26/SUM(H26:I26) -> #DIV/0!
A27: ReCiPe 2016 v1.03, endpoint (E) | total: ecosystem quality | ecosystem quality | G27: ReCiPe 2016 v1.03, endpoint (E) | human health | photochemical oxidant formation: human health | H27: 0 | I27: 0 | J27: DALYs | K27: ReCiPe 2016 v1.03, endpoint (E) | human health | photochemical oxidant formation: human health | L27: =H27/SUM(H27:I27) -> #DIV/0! | M27: =I27/SUM(H27:I27) -> #DIV/0!
A28: ReCiPe 2016 v1.03, endpoint (E) | total: human health | human health | G28: ReCiPe 2016 v1.03, endpoint (E) | human health | water use: human health | H28: 0 | I28: 0 | J28: DALYs | K28: ReCiPe 2016 v1.03, endpoint (E) | human health | water use: human health | L28: =H28/SUM(H28:I28) -> #DIV/0! | M28: =I28/SUM(H28:I28) -> #DIV/0!
A29: ReCiPe 2016 v1.03, endpoint (E) | total: natural resources | natural resources | G29: ReCiPe 2016 v1.03, endpoint (E) | natural resources | energy resources: non-renewable, fossil | H29: 0 | I29: 0 | J29: USD 2013 | K29: ReCiPe 2016 v1.03, endpoint (E) | natural resources | energy resources: non-renewable, fossil | L29: =H29/SUM(H29:I29) -> #DIV/0! | M29: =I29/SUM(H29:I29) -> #DIV/0!
G30: ReCiPe 2016 v1.03, endpoint (E) | natural resources | material resources: metals/minerals | H30: 0 | I30: 0 | J30: USD 2013 | K30: ReCiPe 2016 v1.03, endpoint (E) | natural resources | material resources: metals/minerals | L30: =H30/SUM(H30:I30) -> #DIV/0! | M30: =I30/SUM(H30:I30) -> #DIV/0!
G31: ReCiPe 2016 v1.03, endpoint (E) | total: ecosystem quality | ecosystem quality | H31: 0 | I31: 0 | J31: species.yr | K31: ReCiPe 2016 v1.03, endpoint (E) | total: ecosystem quality | ecosystem quality | L31: =H31/SUM(H31:I31) -> #DIV/0! | M31: =I31/SUM(H31:I31) -> #DIV/0!
A32: Copy and Paste Methode below: | G32: ReCiPe 2016 v1.03, endpoint (E) | total: human health | human health | H32: 0 | I32: 0 | J32: DALYs | K32: ReCiPe 2016 v1.03, endpoint (E) | total: human health | human health | L32: =H32/SUM(H32:I32) -> #DIV/0! | M32: =I32/SUM(H32:I32) -> #DIV/0!
A33: ReCiPe 2016 v1.03, endpoint (E) | total: natural resources | natural resources | G33: ReCiPe 2016 v1.03, endpoint (E) | total: natural resources | natural resources | H33: 0 | I33: 0 | J33: USD 2013 | K33: ReCiPe 2016 v1.03, endpoint (E) | total: natural resources | natural resources | L33: =H33/SUM(H33:I33) -> #DIV/0! | M33: =I33/SUM(H33:I33) -> #DIV/0!

Sheet A. Databases
A1: Data Sheet
H2: CHOSE METHODE HERE
A3: index | B3: amount | C3: unit | D3: reference product | E3: name | F3: location | G3: database | H3: =Macro!C8 -> ReCiPe 2016 v1.03, endpoint (E) | total: natural resources | natural resources | I3: IPCC 2021 | climate change | global warming potential (GWP100) | J3: ReCiPe 2016 v1.03, endpoint (E) | ecosystem quality | acidification: terrestrial | K3: ReCiPe 2016 v1.03, endpoint (E) | ecosystem quality | climate change: freshwater ecosystems | L3: ReCiPe 2016 v1.03, endpoint (E) | ecosystem quality | climate change: terrestrial ecosystems | M3: ReCiPe 2016 v1.03, endpoint (E) | ecosystem quality | ecotoxicity: freshwater | N3: ReCiPe 2016 v1.03, endpoint (E) | ecosystem quality | ecotoxicity: marine | O3: ReCiPe 2016 v1.03, endpoint (E) | ecosystem quality | ecotoxicity: terrestrial | P3: ReCiPe 2016 v1.03, endpoint (E) | ecosystem quality | eutrophication: freshwater | Q3: ReCiPe 2016 v1.03, endpoint (E) | ecosystem quality | eutrophication: marine | R3: ReCiPe 2016 v1.03, endpoint (E) | ecosystem quality | land use | S3: ReCiPe 2016 v1.03, endpoint (E) | ecosystem quality | photochemical oxidant formation: terrestrial ecosystems | T3: ReCiPe 2016 v1.03, endpoint (E) | ecosystem quality | water use: aquatic ecosystems | U3: ReCiPe 2016 v1.03, endpoint (E) | ecosystem quality | water use: terrestrial ecosystems | V3: ReCiPe 2016 v1.03, endpoint (E) | human health | climate change: human health | W3: ReCiPe 2016 v1.03, endpoint (E) | human health | human toxicity: carcinogenic | X3: ReCiPe 2016 v1.03, endpoint (E) | human health | human toxicity: non-carcinogenic | Y3: ReCiPe 2016 v1.03, endpoint (E) | human health | ionising radiation | Z3: ReCiPe 2016 v1.03, endpoint (E) | human health | ozone depletion | AA3: ReCiPe 2016 v1.03, endpoint (E) | human health | particulate matter formation | AB3: ReCiPe 2016 v1.03, endpoint (E) | human health | photochemical oxidant formation: human health | AC3: ReCiPe 2016 v1.03, endpoint (E) | human health | water use: human health | AD3: ReCiPe 2016 v1.03, endpoint (E) | natural resources | energy resources: non-renewable, fossil | AE3: ReCiPe 2016 v1.03, endpoint (E) | natural resources | material resources: metals/minerals | AF3: ReCiPe 2016 v1.03, endpoint (E) | total: ecosystem quality | ecosystem quality | AG3: ReCiPe 2016 v1.03, endpoint (E) | total: human health | human health | AH3: ReCiPe 2016 v1.03, endpoint (E) | total: natural resources | natural resources
A4: dimethyl sulfoxide | dimethyl sulfoxide production | RER | kilogram | ecoinvent-3.10-cutoff | B4: 1 | C4: kilogram | D4: dimethyl sulfoxide | E4: dimethyl sulfoxide production | F4: RER | G4: ecoinvent-3.10-cutoff | H4: =IFERROR(INDEX(I4:AH4,MATCH($H$3,$I$3:$AH$3,0)),"") -> 0
A5: tetrahydrofuran | tetrahydrofuran production | RER | kilogram | ecoinvent-3.10-cutoff | B5: 1 | C5: kilogram | D5: tetrahydrofuran | E5: tetrahydrofuran production | F5: RER | G5: ecoinvent-3.10-cutoff | H5: =IFERROR(INDEX(I5:AH5,MATCH($H$3,$I$3:$AH$3,0)),"") -> 0
A6: acrylonitrile | market for acrylonitrile | GLO | kilogram | ecoinvent-3.10-cutoff | B6: 1 | C6: kilogram | D6: acrylonitrile | E6: market for acrylonitrile | F6: GLO | G6: ecoinvent-3.10-cutoff | H6: =IFERROR(INDEX(I6:AH6,MATCH($H$3,$I$3:$AH$3,0)),"") -> 0
A7: neutralising agent, sodium hydroxide-equivalent | sodium hydroxide to generic market for neutralising agent | RER | kilogram | ecoinvent-3.10-cutoff | B7: 1 | C7: kilogram | D7: neutralising agent, sodium hydroxide-equivalent | E7: sodium hydroxide to generic market for neutralising agent | F7: RER | G7: ecoinvent-3.10-cutoff | H7: =IFERROR(INDEX(I7:AH7,MATCH($H$3,$I$3:$AH$3,0)),"") -> 0
A8: methanol | market for methanol | RoW | kilogram | ecoinvent-3.10-cutoff | B8: 1 | C8: kilogram | D8: methanol | E8: market for methanol | F8: RoW | G8: ecoinvent-3.10-cutoff | H8: =IFERROR(INDEX(I8:AH8,MATCH($H$3,$I$3:$AH$3,0)),"") -> 0
A9: aniline | market for aniline | RER | kilogram | ecoinvent-3.10-cutoff | B9: 1 | C9: kilogram | D9: aniline | E9: market for aniline | F9: RER | G9: ecoinvent-3.10-cutoff | H9: =IFERROR(INDEX(I9:AH9,MATCH($H$3,$I$3:$AH$3,0)),"") -> 0
A10: nitrobenzene | nitrobenzene production | RER | kilogram | ecoinvent-3.10-cutoff | B10: 1 | C10: kilogram | D10: nitrobenzene | E10: nitrobenzene production | F10: RER | G10: ecoinvent-3.10-cutoff | H10: =IFERROR(INDEX(I10:AH10,MATCH($H$3,$I$3:$AH$3,0)),"") -> 0
A11: chloronitrobenzene | chloronitrobenzene production | RER | kilogram | ecoinvent-3.10-cutoff | B11: 1 | C11: kilogram | D11: chloronitrobenzene | E11: chloronitrobenzene production | F11: RER | G11: ecoinvent-3.10-cutoff | H11: =IFERROR(INDEX(I11:AH11,MATCH($H$3,$I$3:$AH$3,0)),"") -> 0
A12: chlorine, gaseous | market for chlorine, gaseous | RER | kilogram | ecoinvent-3.10-cutoff | B12: 1 | C12: kilogram | D12: chlorine, gaseous | E12: market for chlorine, gaseous | F12: RER | G12: ecoinvent-3.10-cutoff | H12: =IFERROR(INDEX(I12:AH12,MATCH($H$3,$I$3:$AH$3,0)),"") -> 0
A13: ammonia, anhydrous, liquid | market for ammonia, anhydrous, liquid | RER | kilogram | ecoinvent-3.10-cutoff | B13: 1 | C13: kilogram | D13: ammonia, anhydrous, liquid | E13: market for ammonia, anhydrous, liquid | F13: RER | G13: ecoinvent-3.10-cutoff | H13: =IFERROR(INDEX(I13:AH13,MATCH($H$3,$I$3:$AH$3,0)),"") -> 0
A14: hydrogen peroxide, without water, in 50% solution state | market for hydrogen peroxide, without water, in 50% solution state | RER | kilogram | ecoinvent-3.10-cutoff | B14: 1 | C14: kilogram | D14: hydrogen peroxide, without water, in 50% solution state | E14: market for hydrogen peroxide, without water, in 50% solution state | F14: RER | G14: ecoinvent-3.10-cutoff | H14: =IFERROR(INDEX(I14:AH14,MATCH($H$3,$I$3:$AH$3,0)),"") -> 0
A15: magnesium sulfate | market for magnesium sulfate | GLO | kilogram | ecoinvent-3.10-cutoff | B15: 1 | C15: kilogram | D15: magnesium sulfate | E15: market for magnesium sulfate | F15: GLO | G15: ecoinvent-3.10-cutoff | H15: =IFERROR(INDEX(I15:AH15,MATCH($H$3,$I$3:$AH$3,0)),"") -> 0
... A44: acetonitrile | Sohio process | RER | kilogram | Ecoinvent 3.9.1 | B44: 1 | C44: kilogram | D44: acetonitrile | E44: Sohio process | F44: RER | G44: Ecoinvent 3.9.1-cutoff | H44: =IFERROR(INDEX(I44:AH44,MATCH($H$3,$I$3:$AH$3,0)),"") -> 0
A45: =D45 -> CPME | B45: 1 | C45: kilogram | D45: CPME | E45: - | F45: - | G45: Economic Allocation | H45: =IFERROR(INDEX(I45:AH45,MATCH($H$3,$I$3:$AH$3,0)),"") -> 0
A46: =D46 -> 2-Methyl THF | B46: 1 | C46: kilogram | D46: 2-Methyl THF | E46: - | F46: - | G46: Economic Allocation | H46: =IFERROR(INDEX(I46:AH46,MATCH($H$3,$I$3:$AH$3,0)),"") -> 0
A47: methyl tert-butyl ether | methyl tert-butyl ether production | RoW | kilogram | Ecoinvent 3.9.1 | B47: 1 | C47: kilogram | D47: methyl tert-butyl ether | E47: methyl tert-butyl ether production | F47: RoW | G47: Ecoinvent 3.9.1-cutoff | H47: =IFERROR(INDEX(I47:AH47,MATCH($H$3,$I$3:$AH$3,0)),"") -> 0
A48: sulfur trioxide | market for sulfur trioxide | RER | kilogram | ecoinvent-3.10-cutoff | B48: 1 | C48: kilogram | D48: sulfur trioxide | E48: market for sulfur trioxide | F48: RER | G48: ecoinvent-3.10-cutoff | H48: =IFERROR(INDEX(I48:AH48,MATCH($H$3,$I$3:$AH$3,0)),"") -> 0
A49: methyl acrylate | methyl acrylate production | GLO | kilogram | ecoinvent-3.10-cutoff | B49: 1 | C49: kilogram | D49: methyl acrylate | E49: methyl acrylate production | F49: GLO | G49: ecoinvent-3.10-cutoff | H49: =IFERROR(INDEX(I49:AH49,MATCH($H$3,$I$3:$AH$3,0)),"") -> 0
A50: salicylic acid | salicylic acid production | GLO | kilogram | ecoinvent-3.10-cutoff | B50: 1 | C50: kilogram | D50: salicylic acid | E50: salicylic acid production | F50: GLO | G50: ecoinvent-3.10-cutoff | H50: =IFERROR(INDEX(I50:AH50,MATCH($H$3,$I$3:$AH$3,0)),"") -> 0
A51: dichloromethane | dichloromethane production | RER | kilogram | ecoinvent-3.10-cutoff | B51: 1 | C51: kilogram | D51: dichloromethane | E51: dichloromethane production | F51: RER | G51: ecoinvent-3.10-cutoff | H51: =IFERROR(INDEX(I51:AH51,MATCH($H$3,$I$3:$AH$3,0)),"") -> 0
A52: phosphorus pentachloride | phosphorus pentachloride production | RoW | kilogram | ecoinvent-3.10-cutoff | B52: 1 | C52: kilogram | D52: phosphorus pentachloride | E52: phosphorus pentachloride production | F52: RoW | G52: ecoinvent-3.10-cutoff | H52: =IFERROR(INDEX(I52:AH52,MATCH($H$3,$I$3:$AH$3,0)),"") -> 0
A53: bromine | bromine production | RER | kilogram | ecoinvent-3.10-cutoff | B53: 1 | C53: kilogram | D53: bromine | E53: bromine production | F53: RER | G53: ecoinvent-3.10-cutoff | H53: =IFERROR(INDEX(I53:AH53,MATCH($H$3,$I$3:$AH$3,0)),"") -> 0
A54: sodium phosphate | sodium phosphate production | RER | kilogram | ecoinvent-3.10-cutoff | B54: 1 | C54: kilogram | D54: sodium phosphate | E54: sodium phosphate production | F54: RER | G54: ecoinvent-3.10-cutoff | H54: =IFERROR(INDEX(I54:AH54,MATCH($H$3,$I$3:$AH$3,0)),"") -> 0
A55: aminopyridine | aminopyridine production, Chichibabin amination | RER | kilogram | ecoinvent-3.10-cutoff | B55: 1 | C55: kilogram | D55: aminopyridine | E55: aminopyridine production, Chichibabin amination | F55: RER | G55: ecoinvent-3.10-cutoff | H55: =IFERROR(INDEX(I55:AH55,MATCH($H$3,$I$3:$AH$3,0)),"") -> 0
A56: potassium hydroxide | potassium hydroxide production | RER | kilogram | ecoinvent-3.10-cutoff | B56: 1 | C56: kilogram | D56: potassium hydroxide | E56: potassium hydroxide production | F56: RER | G56: ecoinvent-3.10-cutoff | H56: =IFERROR(INDEX(I56:AH56,MATCH($H$3,$I$3:$AH$3,0)),"") -> 0
A57: citric acid | citric acid production | RER | kilogram | ecoinvent-3.10-cutoff | B57: 1 | C57: kilogram | D57: citric acid | E57: citric acid production | F57: RER | G57: ecoinvent-3.10-cutoff | H57: =IFERROR(INDEX(I57:AH57,MATCH($H$3,$I$3:$AH$3,0)),"") -> 0
A58: 3-methylpyridine | 3-methylpyridine production | RER | kilogram | ecoinvent-3.10-cutoff | B58: 1 | C58: kilogram | D58: 3-methylpyridine | E58: 3-methylpyridine production | F58: RER | G58: ecoinvent-3.10-cutoff | H58: =IFERROR(INDEX(I58:AH58,MATCH($H$3,$I$3:$AH$3,0)),"") -> 0
... A66: acetaldehyde | acetaldehyde production, ethylene oxidation | RER | kilogram | ecoinvent-3.10-cutoff | B66: 1 | C66: kilogram | D66: acetaldehyde | E66: acetaldehyde production, ethylene oxidation | F66: RER | G66: ecoinvent-3.10-cutoff | H66: =IFERROR(INDEX(I66:AH66,MATCH($H$3,$I$3:$AH$3,0)),"") -> 0
A67: =D67 -> thionyl chloride | B67: 1 | C67: kilogram | D67: thionyl chloride | E67: thionyl chloride production | F67: RER | G67: Ecoinvent 3.9.1 | H67: =IFERROR(INDEX(I67:AH67,MATCH($H$3,$I$3:$AH$3,0)),"") -> 0
A68: =D68 -> lithium aluminium hydride | B68: 1 | C68: kilogram | D68: lithium aluminium hydride | E68: market for lithium aluminium hydride | F68: GLO | G68: ecoinvent-3.11-cutoff | H68: =IFERROR(INDEX(I68:AH68,MATCH($H$3,$I$3:$AH$3,0)),"") -> 0
A69: acetyl chloride | acetyl chloride production | RER | kilogram | ecoinvent-3.10-cutoff | B69: 1 | C69: kilogram | D69: acetyl chloride | E69: acetyl chloride production | F69: RER | G69: ecoinvent-3.10-cutoff | H69: =IFERROR(INDEX(I69:AH69,MATCH($H$3,$I$3:$AH$3,0)),"") -> 0
A70: triethyl amine | market for triethyl amine | GLO | kilogram | ecoinvent-3.10-cutoff | B70: 1 | C70: kilogram | D70: triethyl amine | E70: market for triethyl amine | F70: GLO | G70: ecoinvent-3.10-cutoff | H70: =IFERROR(INDEX(I70:AH70,MATCH($H$3,$I$3:$AH$3,0)),"") -> 0
A71: pyridine | market for pyridine | GLO | kilogram | ecoinvent-3.10-cutoff | B71: 1 | C71: kilogram | D71: pyridine | E71: market for pyridine | F71: GLO | G71: ecoinvent-3.10-cutoff | H71: =IFERROR(INDEX(I71:AH71,MATCH($H$3,$I$3:$AH$3,0)),"") -> 0
A72: dimethylamine | market for dimethylamine | RER | kilogram | ecoinvent-3.10-cutoff | B72: 1 | C72: kilogram | D72: dimethylamine | E72: market for dimethylamine | F72: RER | G72: ecoinvent-3.10-cutoff | H72: =IFERROR(INDEX(I72:AH72,MATCH($H$3,$I$3:$AH$3,0)),"") -> 0
A73: alpha-naphthol | market for alpha-naphthol | GLO | kilogram | ecoinvent-3.10-cutoff | B73: 1 | C73: kilogram | D73: alpha-naphthol | E73: market for alpha-naphthol | F73: GLO | G73: ecoinvent-3.10-cutoff | H73: =IFERROR(INDEX(I73:AH73,MATCH($H$3,$I$3:$AH$3,0)),"") -> 0
A74: iron(III) chloride, without water, in 40% solution state | market for iron(III) chloride, without water, in 40% solution state | GLO | kilogram | ecoinvent-3.10-cutoff | B74: 1 | C74: kilogram | D74: iron(III) chloride, without water, in 40% solution state | E74: market for iron(III) chloride, without water, in 40% solution state | F74: GLO | G74: ecoinvent-3.10-cutoff | H74: =IFERROR(INDEX(I74:AH74,MATCH($H$3,$I$3:$AH$3,0)),"") -> 0
A75: water, completely softened | market for water, completely softened | RER | kilogram | ecoinvent-3.10-cutoff | B75: 1 | C75: kilogram | D75: water, completely softened | E75: market for water, completely softened | F75: RER | G75: ecoinvent-3.10-cutoff | H75: =IFERROR(INDEX(I75:AH75,MATCH($H$3,$I$3:$AH$3,0)),"") -> 0
...

Sheet 1.1 LCA This Work FU
A1: Letermovir 1kg cumulative NCCR
A3: Step 1 | B3: Synthesis of Methyl-(E)-3-(2-amino-3-fluorophenyl)acrylate | J3: Ref
A5: Reactants | B5: Given Stoichiometry | C5: Unit | D5: Moles | E5: Unit | F5: Mass Stoich | G5: Unit | H5: GWP kgCO2-eq/kg | I5: GWP kgCO2-eq
A6: 2-amino-3-fluorobenzoic acid | B6: 155.13 | C6: MW | D6: =F6*1000/B6 -> 3.8728092 | E6: mol | F6: =D14*B6/1000/B12 -> 0.60078889 | G6: kg | H6: ='B.4. Precursors'!G19 -> 0 | I6: =H6*F6 -> 0
A7: BH3SMe3 | B7: 75.96 | C7: MW | D7: =D6*(3.867/3.223) -> 4.6466501 | E7: mol | F7: =(D14*B7/1000)/B12 -> 0.29417859 | G7: kg | H7: ='B.4. Precursors'!G65 -> 0 | I7: =H7*F7 -> 0
A8: 1 M NaOH | B8: =10/0.5 -> 20 | C8: mass equiv | F8: =F6*B8*0.039 -> 0.46861533 | G8: kg | H8: ='A. Databases'!H20 -> 0 | I8: =H8*F8 -> 0 | J8: 1M 3.9 wt%
A9: Solvents | B9: Given Stoichiometry | C9: Unit | F9: Mass Stoich | G9: Unit
A10: 2-Me-THF | B10: =2.562/0.5 -> 5.124 | C10: mass equiv | D10: - | E10: - | F10: =B10*F6 -> 3.0784423 | G10: kg | H10: ='A. Databases'!$H$46 -> 0 | I10: =H10*F10 -> 0
A11: MeOH | B11: =0.4131/0.5 -> 0.8262 | C11: mass equiv | F11: =B11*F6 -> 0.49637178 | G11: kg | H11: ='A. Databases'!H8 -> 0 | I11: =H11*F11 -> 0
A12: Yield | B12: 0.99
A13: Product | B13: Given Stoichiometry | C13: Unit | D13: Moles | E13: Unit | F13: Mass Stoich | G13: Unit
A14: 2 | B14: 141.15 | C14: MW | D14: =F14/(B14/1000) -> 3.8340811 | E14: mol | F14: =F20 -> 0.54118055 | G14: kg | H14: =I14/F14 -> 0 | I14: =SUM(I6,I7,I8,I10,I11) -> 0
A17: Step 2 | B17: Synthesis of Methyl-(E)-3-(3-flururo-2-((phenoxycarbonyl)amino)-phenyl)acrylate | J17: Ref
A19: Reactants | B19: Given Stoichiometry | C19: Unit | D19: Moles | E19: Unit | F19: Mass Stoich | G19: Unit | H19: GWP kgCO2-eq/kg | I19: GWP kgCO2-eq
A20: 2 | B20: 141.15 | C20: MW | D20: =F20*1000/B20 -> 3.8340811 | E20: mol | F20: =B20*D28/1000/B26 -> 0.54118055 | G20: kg | H20: =H14 -> 0 | I20: =H20*F20 -> 0
A21: 2-isothiocyanato-1-methoxy-4-(trifluoromethyl)benzene | B21: 233.21 | C21: MW | D21: =F21*1000/B21 -> 3.9855273 | E21: mol | F21: =D28*B21*1.05/1000 -> 0.92946482 | G21: kg | H21: ='B.4. Precursors'!$G$60 -> 0 | I21: =H21*F21 -> 0
A23: Solvents | B23: Given Stoichiometry | C23: Unit | F23: Mass Stoich | G23: Unit
A24: MeOH | B24: 5.8588146 | F24: =F20*B24 -> 3.1706765 | G24: kg | H24: ='A. Databases'!H33 -> 0 | I24: =H24*F24 -> 0
A26: Yield | B26: 0.99
A27: Product | B27: Given Stoichiometry | C27: Unit | D27: Moles | F27: Mass Stoich | G27: Unit
A28: 3 | B28: 374.35 | C28: MW | D28: =F28/(B28/1000) -> 3.7957403 | F28: =F34 -> 1.4209354 | G28: kg | H28: =I28/F28 -> 0 | I28: =SUM(I20,I21,I24,I25) -> 0
A31: Step 3 | B31: Synthesis of Methyl-(E)-3-(3-fluoro-2-(3-(2-methoxy-5-(trifluoromethyl)phenyl)ureido)phenyl)acrylate | J31: Ref
A33: Reactants | B33: Given Stoichiometry | C33: Unit | D33: Moles | E33: Unit | F33: Mass Stoich | G33: Unit | H33: GWP kgCO2-eq/kg | I33: GWP kgCO2-eq
A34: 3 | B34: 374.35 | C34: MW | D34: =F34*1000/B34 -> 3.7957403 | E34: mol | F34: =D42*B34/1000/B40 -> 1.4209354 | G34: kg | H34: =H28 -> 0 | I34: =H34*F34 -> 0
A35: AcCl | B35: 78.49 | C35: MW | D35: =F35*1000/B35 -> 3.7957403 | E35: mol | F35: =B35*D42/1000/B40 -> 0.29792765 | G35: kg | H35: ='A. Databases'!$H$69 -> 0 | I35: =H35*F35 -> 0
A37: Solvents | B37: Given Stoichiometry | C37: Unit | F37: Mass Stoich | G37: Unit
A38: MeOH | B38: 0.73636229 | C38: Mass Equiv | D38: - | E38: - | F38: =F34*B38 -> 1.0463232 | G38: kg | H38: ='A. Databases'!H33 -> 0 | I38: =H38*F38 -> 0
A40: Yield | B40: 0.99
A41: Product | B41: Given Stoichiometry | C41: Unit | D41: Moles | E41: Unit | F41: Mass Stoich | G41: Unit
A42: 4 | B42: 356.34 | C42: MW | D42: =F42/(B42/1000) -> 3.7577829 | E42: mol | F42: =F48 -> 1.3390484 | G42: kg | H42: =I42/F42 -> 0 | I42: =SUM(I34,I35,I38,I39,I36) -> 0
A45: Step 4 | B45: Synthesis of Methyl-(E)-3-(3-fluoro-2-((((2-methoxy-5-(trifluroromethyl)phenyl)imino)methylene)amino)phenyl)acrylate | J45: Ref
A47: Reactants | B47: Given Stoichiometry | C47: Unit | D47: Moles | E47: Unit | F47: Mass Stoich | G47: Unit | H47: GWP kgCO2-eq/kg | I47: GWP kgCO2-eq
A48: 4 | B48: 356.34 | C48: MW | D48: =D58/B56 -> 3.7577829 | E48: mol | F48: =D48*B48/1000 -> 1.3390484 | G48: kg | H48: =H42 -> 0 | I48: =H48*F48 -> 0
A49: Magnesium (monoperoxyphthalate)2 | B49: 386.551 | C49: MW | D49: =0.7*D48 -> 2.630448 | E49: mol | F49: =D49*B49/1000 -> 1.0168023 | G49: kg | H49: ='B.4. Precursors'!G71 -> 0 | I49: =H49*F49 -> 0
A50: aq. NaHCO3 | B50: 20 | C50: mass equiv | F50: =B50*F48*0.096 -> 2.5709728 | G50: kg | H50: ='A. Databases'!H107 -> 0 | I50: =H50*F50 -> 0 | J50: aq. 9.8 wt%
A51: TFAA | B51: 210.03 | C51: MW | D51: 4.301 | E51: mol | F51: =D51*B51/1000 -> 0.90333903 | G51: kg | H51: ='B.4. Precursors'!G42 -> 0 | I51: =H51*F51 -> 0
A52: NEt3 | B52: 101.19 | C52: MW | D52: =1*D48 -> 3.7577829 | E52: mol | F52: =D52*B52/1000 -> 0.38025005 | G52: kg | H52: ='A. Databases'!$H$70 -> 0 | I52: =H52*F52 -> 0
A53: Solvents | B53: Given Stoichiometry | C53: Unit | F53: Mass Stoich | G53: Unit
A54: 2-Me-THF | B54: 4.46 | C54: Mass Equiv | D54: - | E54: - | F54: =F48*B54 -> 5.9721556 | G54: kg | H54: ='A. Databases'!H46 -> 0 | I54: =H54*F54 -> 0
A55: MeOH | B55: 4.4183378 | C55: Mass Equiv | F55: =F48*B55 -> 5.916368 | G55: kg | H55: ='A. Databases'!H33 -> 0 | I55: =H55*F55 -> 0
...

Sheet 2.1. Merck LCA FU
A1: Letermovir 1 kg accumulative
A3: Step 1 | B3: Synthesis of Methyl-(E)-3-(2-amino-3-fluorophenyl)acrylate | J3: PMI
H4: Impact Share | J4: =(D6+D7+D8+D10+D11)/D14 -> 13.795694
A5: Reactants | B5: Given Stoichiometry | C5: Unit | D5: Mass Stoich | E5: Unit | F5: GWP kgCO2-eq/kg | G5: GWP kgCO2-eq | H5: Starting Materials | I5: =SUM(G6,G7) -> 0
A6: 2-bromo-6-fluoroaniline | B6: 1.3 | C6: kg | D6: =($D$14/$B$14)*B6 -> 0.95588707 | E6: kg | F6: ='B.4. Precursors'!$G$6 -> 0 | G6: =F6*D6 -> 0 | H6: Reagents | I6: 0
A7: Methyl acrylate | B7: 1.17 | C7: kg | D7: =($D$14/$B$14)*B7 -> 0.86029836 | E7: kg | F7: ='A. Databases'!$H$21 -> 0 | G7: =F7*D7 -> 0 | H7: Catalysts | I7: =G8 -> 0
A8: (t-Bu)3P-Pd G2 | B8: 0.0262 | C8: kg | D8: =($D$14/$B$14)*B8 -> 0.019264801 | E8: kg | F8: ='B.3. Pd Catalyst'!$F$44 -> 0 | G8: =F8*D8 -> 0 | H8: Solvent | I8: =SUM(G10:G11) -> 0
A9: Solvents | B9: Given Stoichiometry | C9: Unit | D9: Mass Stoich | E9: Unit
A10: iProAc | B10: 9.05 | C10: kg | D10: =($D$14/$B$14)*B10 -> 6.6544446 | E10: kg | F10: ='A. Databases'!$H$35 -> 0 | G10: =F10*D10 -> 0
A11: iProAc | B11: 6.78 | C11: kg | D11: =($D$14/$B$14)*B11 -> 4.9853187 | E11: kg | F11: ='A. Databases'!$H$35 -> 0 | G11: =F11*D11 -> 0
A13: Product | B13: Given Stoichiometry | C13: Unit | D13: Mass Stoich | E13: Unit
A14: 15 | B14: 1.3284 | C14: kg | D14: =D22 -> 0.97676952 | E14: kg | F14: =G14/D14 -> 0 | G14: =SUM(G6,G7,G8,G10,G11) -> 0
A19: Step 2 | B19: Synthesis of Methyl-(E)-3-(3-flururo-2-((phenoxycarbonyl)amino)-phenyl)acrylate | J19: PMI
H20: Impact Share | J20: =(D22+D23+D24+D26+D27)/D30 -> 15.515802
A21: Reactants | B21: Given Stoichiometry | C21: Unit | D21: Mass Stoich | E21: Unit | F21: GWP kgCO2-eq/kg | G21: GWP kgCO2-eq | H21: Starting Materials | I21: =G22 -> 0
A22: 15 | B22: 1.3038 | C22: kg | D22: =($D$30/$B$30)*B22 -> 0.97676952 | E22: kg | F22: =$F$14 -> 0 | G22: =F22*D22 -> 0 | H22: Reagents | I22: =G23+G24 -> 0
A23: Na2HPO4 | B23: 1.42 | C23: kg | D23: =($D$30/$B$30)*B23 -> 1.0638232 | E23: kg | F23: ='A. Databases'!$H$54 -> 0 | G23: =F23*D23 -> 0 | H23: Catalysts | I23: 0
A24: Phenyl chloroformate | B24: 1.3042281 | C24: kg | D24: =($D$30/$B$30)*B24 -> 0.97709024 | E24: kg | F24: ='B.4. Precursors'!I119 -> 0 | G24: =F24*D24 -> 0 | H24: Solvent | I24: =SUM(G26:G27) -> 0
A25: Solvents | B25: Given Stoichiometry | C25: Unit | D25: Mass Stoich | E25: Unit
A26: H2O | B26: 9.1 | C26: kg | D26: =($D$30/$B$30)*B26 -> 6.8174587 | E26: kg | F26: ='A. Databases'!$H$38 -> 0 | G26: =F26*D26 -> 0
A27: iProAc | B27: 6.09 | C27: kg | D27: =($D$30/$B$30)*B27 -> 4.5624531 | E27: kg | F27: ='A. Databases'!$H$35 -> 0 | G27: =F27*D27 -> 0
A29: Product | B29: Given Stoichiometry | C29: Unit | D29: Mass Stoich | E29: Unit
A30: 16 | B30: 1.23861 | C30: kg | D30: =D36 -> 0.92793105 | E30: kg | F30: =G30/D30 -> 0 | G30: =SUM(G22,G23,G26,G27,G24) -> 0
A33: Step 3 | B33: Synthesis of Methyl-(E)-3-(3-fluoro-2-(3-(2-methoxy-5-(trifluoromethyl)phenyl)ureido)phenyl)acrylate | J33: PMI
H34: Impact Share | J34: =(D36+D37+D38+D40)/D44 -> 2.918235
A35: Reactants | B35: Given Stoichiometry | C35: Unit | D35: Mass Stoich | E35: Unit | F35: GWP kgCO2-eq/kg | G35: GWP kgCO2-eq | H35: Starting Materials | I35: =G36 -> 0
A36: 16 | B36: 2.099898 | C36: kg | D36: =($D$44/$B$44)*B36 -> 0.92793105 | E36: kg | F36: =$F$30 -> 0 | G36: =F36*D36 -> 0 | H36: Reagents | I36: =SUM(G37:G38) -> 0
A37: 3 | B37: 1.4 | C37: kg | D37: =($D$44/$B$44)*B37 -> 0.61865075 | E37: kg | F37: ='B.4. Precursors'!D60 -> 0 | G37: =F37*D37 -> 0 | H37: Catalysts
A38: DMAP | B38: 0.0405 | C38: kg | D38: =($D$44/$B$44)*B38 -> 0.017896682 | E38: kg | F38: ='B.4. Precursors'!$G$35 -> 0 | G38: =F38*D38 -> 0 | H38: Solvent | I38: =G40 -> 0
A39: Solvents | B39: Given Stoichiometry | C39: Unit | D39: Mass Stoich | E39: Unit
A40: iProAc | B40: 3.48 | C40: kg | D40: =($D$44/$B$44)*B40 -> 1.537789 | E40: kg | F40: ='A. Databases'!$H$35 -> 0 | G40: =F40*D40 -> 0
A43: Product | B43: Given Stoichiometry | C43: Unit | D43: Mass Stoich | E43: Unit
A44: 5 | B44: 2.4057 | C44: kg | D44: =D50 -> 1.0630629 | E44: kg | F44: =G44/D44 -> 0 | G44: =SUM(G36,G37,G40,G41,G38) -> 0
A47: Step 4 | B47: Synthesis of Methyl-(E)-3-(3-fluoro-2-((((2-methoxy-5-(trifluroromethyl)phenyl)imino)methylene)amino)phenyl)acrylate | J47: PMI
H48: Impact Share | J48: =(D50+D51+D52+D53+D54+D56+D57)/D60 -> 22.189773
A49: Reactants | B49: Given Stoichiometry | C49: Unit | D49: Mass Stoich | E49: Unit | F49: GWP kgCO2-eq/kg | G49: GWP kgCO2-eq | H49: Starting Materials | I49: =G50 -> 0
A50: 5 | B50: 2 | C50: kg | D50: =($D$60/$B$60)*B50 -> 1.0630629 | E50: kg | F50: =$F$44 -> 0 | G50: =F50*D50 -> 0 | H50: Reagents | I50: =SUM(G51:G54) -> 0
A51: PCl5 | B51: 1.24 | C51: kg | D51: =($D$60/$B$60)*B51 -> 0.65909902 | E51: kg | F51: ='A. Databases'!$H$25 -> 0 | G51: =F51*D51 -> 0 | H51: Catalysts | I51: 0
A52: 2- picoline | B52: 1.36 | C52: kg | D52: =($D$60/$B$60)*B52 -> 0.72288279 | E52: kg | F52: ='A. Databases'!$H$62 -> 0 | G52: =F52*D52 -> 0 | H52: Solvent | I52: =SUM(G56:G57) -> 0
A53: KOH | B53: 1.632 | C53: kg | D53: =($D$60/$B$60)*B53 -> 0.86745935 | E53: kg | F53: ='A. Databases'!$H$56 -> 0 | G53: =D53*F53 -> 0
...

Sheet B.1. Chiral Cat This Work
A1: Step 1 | B1: Synthesis of 1,1'-bi-2-napthhol | J1: Yield | K1: Product mass | N1: Step 1
A2: Chemicals | B2: MW | C2: Masse | D2: Volumen | E2: Density | F2: mmol | G2: equiv | J2: 0.96 | K2: 3.80 g
A3: 2-Naphthol | B3: 144.06 | C3: 4.03 g | F3: 28 | G3: 1 | N3: Reactants | O3: Given Stoichiometry | P3: Unit | Q3: Moles | R3: Unit | S3: Mass Stoich | T3: Unit | U3: GWP kgCO2-eq/kg | V3: GWP kgCO2-eq
A4: FeCl3 . 6H2O | B4: 270.3 | C4: 15.14 g | F4: 56 | G4: 2 | N4: 2-Naphthol | P4: MW | S4: 0.00403 | T4: kg | U4: ='A. Databases'!H73 -> 0 | V4: =U4*S4 -> 0
A5: H2O | D5: 200 mL | N5: FeCl3 . 6H2O | P5: MW | S5: 0.01514 | T5: kg | U5: ='A. Databases'!H74 -> 0 | V5: =U5*S5 -> 0
A6: Ethanol | D6: 40 mL | T6: kg
N7: Solvents | O7: Given Stoichiometry | P7: Unit | S7: Mass Stoich | T7: Unit
N8: H2O | P8: kg | S8: 0.2 | T8: kg | U8: ='A. Databases'!H75 -> 0 | V8: =U8*S8 -> 0
A9: Step 2 | B9: Chiral resolution of 1,1'-bi-2-napthhol | J9: Yield | K9: Product mass | N9: Ethanol | S9: 0.04 | T9: kg | U9: ='A. Databases'!H76 -> 0 | V9: =U9*S9 -> 0
A10: Chemicals | B10: MW | C10: Masse | D10: Volumen | E10: Density | F10: mmol | G10: equiv | I10: (S) | J10: 89-93% | K10: 10.28-10.65 g | N10: Yield
A11: 1,1'-bi-2-napthhol | B11: 286.1 | C11: 23.0 g | F11: 80 | G11: 1 | N11: Product | O11: Given Stoichiometry | P11: Unit | S11: Mass Stoich | T11: Unit
A12: N-benzylcinchonidinium chloride | B12: 420.2 | C12: 18.6 g | F12: 44 | G12: 0.55 | N12: 1,1'-bi-2-napthhol | P12: MW | R12: mol | S12: 0.0038 | T12: kg | U12: =V12/S12 -> 0 | V12: =SUM(V4:V11) -> 0
A13: Acetonitrile | D13: 300 mL
A14: Ethyl acetate | D14: 300 mL
A15: HCl (1N aquoues) | D15: 200 mL
A16: sat. aq. NaCl | D16: 100 mL
A17: Solid that was filtered off from step 2.1 was recrystallized
A18: Acetonitrile | D18: 50 mL | I18: ( R) | J18: 85-88% | K18: 9.83-10.16 g | N18: Step 2
A19: Methanol | D19: 120 mL
A20: Ethyl acetate | D20: 300 mL | N20: Reactants | O20: Given Stoichiometry | P20: Unit | Q20: Moles | R20: Unit | S20: Mass Stoich | T20: Unit | U20: GWP kgCO2-eq/kg | V20: GWP kgCO2-eq
A21: HCl (1N aquoues) | D21: 300 mL | N21: 1,1'-bi-2-napthhol | P21: MW | S21: 0.023 | T21: kg | U21: =U12 -> 0 | V21: =U21*S21 -> 0
A22: sat. aq. NaCl | D22: 150 mL | N22: N-benzylcinchonidinium chloride | P22: MW | S22: 0.0186 | T22: kg
A25: Step 3 | B25: MOM-protection | J25: Yield | K25: Product mass
A26: Chemicals | B26: MW | C26: Masse | D26: Volumen | E26: Density | F26: mmol | G26: equiv | J26: 1 | K26: 12.42 g | N26: Solvents | O26: Given Stoichiometry | P26: Unit | S26: Mass Stoich | T26: Unit
A27: 1,1'-bi-2-napthhol | B27: 286.1 | C27: 9.5 g | F27: 33.2 | G27: 1 | N27: Acetonitrile | O27: 300 mL | P27: ml | S27: 0.3 | T27: kg | U27: ='A. Databases'!H77 -> 0 | V27: =U27*S27 -> 0
A28: chloromethyl methyl ether | B28: 80 | D28: 5.54 | E28: 1.06 | F28: 73 | G28: 2.2 | N28: Ethyl acetate | O28: 300 mL | P28: ml | S28: 0.3 | T28: kg | U28: ='A. Databases'!H78 -> 0 | V28: =U28*S28 -> 0
A29: Sodium hydride (60% in oil) | C29: 2.92 | F29: 73 | G29: 2.2 | N29: HCl (1N aquoues) | O29: 200 mL | P29: ml | S29: 0.2 | T29: kg | U29: ='A. Databases'!H79/16 -> 0 | V29: =U29*S29 -> 0
A30: THF | D30: 200 mL | N30: sat. aq. NaCl | O30: 100 mL | P30: ml | S30: 1 | T30: kg | U30: ='A. Databases'!H81 -> 0 | V30: =U30*S30 -> 0
A31: NH4Cl sat. aq. | D31: 50 mL | N31: Acetonitrile | O31: 50 mL | P31: ml | S31: 0.05 | T31: kg | U31: ='A. Databases'!H77 -> 0 | V31: =U31*S31 -> 0
A32: CH2Cl2 | D32: 150 mL | N32: Methanol | O32: 120 mL | P32: ml | S32: 0.12 | T32: kg | U32: ='A. Databases'!H80 -> 0 | V32: =U32*S32 -> 0
A33: sat. aq. NaCl | D33: 50 mL | N33: Ethyl acetate | O33: 300 mL | P33: ml | S33: 0.3 | T33: kg | U33: ='A. Databases'!H78 -> 0 | V33: =U33*S33 -> 0
N34: HCl (1N aquoues) | O34: 300 mL | P34: ml | S34: 0.3 | T34: kg | U34: ='A. Databases'!H79/16 -> 0 | V34: =U34*S34 -> 0
A35: purification by column chromatography with EtOAc/hexane and then recrystallization from CH2Cl2/Hex
A37: Step 4 | B37: ortho-Bpin | J37: Yield | K37: Product mass | N37: Yield
A38: Chemicals | B38: MW | C38: Masse | D38: Volumen | E38: Density | F38: mmol | G38: equiv | J38: 0.9 | K38: 15.03 | N38: Product | O38: Given Stoichiometry | P38: Unit | S38: Mass Stoich | T38: Unit
A39: 2,2’-bis(methoxymethoxy)- 1,1’-binaphthyl | B39: 374.15 | C39: 10.00 g | F39: 26.7 | G39: 1 | P39: MW | R39: mol | S39: 0.01016 | T39: kg | U39: =V39/S39/2 -> 0 | V39: =SUM(V21:V37) -> 0 | W39: Alloaction of enantiomer, divided by 2
A40: Diethylether | D40: 300 mL
A41: n-BuLi (1.6M in hexane) | D41: 50.0 mL | F41: 80 | G41: 3
A42: i-PrOBPin (2-isopropoxy-4,4,5,5-tetramethyl -1,3,2-dioxaborolane) | D42: 21.8 mL | F42: 106.8 | G42: 4
A43: NH4Cl sat. aq. | D43: unknown | N43: Step 3
...

Sheet B.2. Chiral Cat Merck
A1: Step 1
A3: Reactants | B3: molecular weight | C3: Unit | D3: Moles | E3: Unit | F3: Mass Stoich | G3: Unit | H3: GWP kgCO2-eq/kg | I3: GWP kgCO2-eq
A4: O[C@@H]([C@@H]1C[C@@H]2CC[N@]1C[C@@H]2C=C)C3=CC=NC4=C3C=CC=C4 | B4: 294.4 | C4: MW | D4: 1 | E4: mol | F4: =B4/1000 -> 0.2944 | G4: kg | H4: ='A. Databases'!H94 -> 123.37457 | I4: =H4*F4 -> 36.321474
A5: BrCC1=CC(C(F)(F)F)=CC(C(F)(F)F)=C1 | B5: 307.03 | C5: MW | D5: 1 | E5: mol | F5: =B5/1000 -> 0.30703 | G5: kg | H5: =H95 -> 0 | I5: =H5*F5 -> 0
A6: BrCC1=CC=CC(C(F)(F)F)=C1 | B6: 239.04 | C6: MW | D6: =263/175 -> 1.5028571 | E6: mol | F6: =B6/1000 -> 0.23904 | G6: kg | H6: =R95 -> 0 | I6: =H6*F6 -> 0
A7: Solvents | B7: Given Stoichiometry | C7: Unit | D7: Density | F7: Mass Stoich | G7: Unit
A8: MeCN | B8: =7/8*840 -> 735 | C8: ml | D8: 0.786 | F8: =B8*D8/1000 -> 0.57771 | G8: kg | H8: ='A. Databases'!H6 -> 0 | I8: =H8*F8 -> 0
A9: EtOAc | B9: 3500 | C9: ml | D9: 0.902 | F9: =B9*D9/1000 -> 3.157 | G9: kg | H9: ='A. Databases'!H19 -> 0 | I9: =H9*F9 -> 0
A10: iProAc | B10: =1/8*840 -> 105 | C10: ml | D10: 0.87 | F10: =B10*D10/1000 -> 0.09135 | G10: kg | H10: ='A. Databases'!H18 -> 0 | I10: =H10*F10 -> 0
A11: Yield | B11: 0.91
A12: Product | B12: Given Stoichiometry | C12: Unit | D12: Moles | E12: Unit | F12: Mass Stoich | G12: Unit
A13: O[C@@H]([C@@H]1C[C@@H]2CC[N@@+]1(CC3=CC(C(F)(F)F)=CC(C(F)(F)F)=C3)C[C@@H]2C=C)C(C4=C5C=CC=C4)=CC=[N+]5CC6=CC=CC(C(F)(F)F)=C6 | B13: 840.47 | C13: MW | D13: 1 | E13: mol | F13: =B13/1000 -> 0.84047 | G13: kg | H13: =I13/F13/B11 -> 47.489746 | I13: =SUM(I4:I11) -> 36.321474
A17: Reagents Production (BrCC1=CC(C(F)(F)F)=CC(C(F)(F)F)=C1) | K17: Reagents Production BrCC1=CC=CC(C(F)(F)F)=C1
A19: Step 1 | K19: Step 1
A21: Reactants | B21: molecular weight | C21: Unit | D21: Moles | E21: Unit | F21: Mass Stoich | G21: Unit | H21: GWP kgCO2-eq/kg | I21: GWP kgCO2-eq | K21: Reactants | L21: molecular weight | M21: Unit | N21: Moles | O21: Unit | P21: Mass Stoich | Q21: Unit | R21: GWP kgCO2-eq/kg | S21: GWP kgCO2-eq
A22: CC1=CC(C)=CC=C1 | B22: 106.17 | C22: MW | D22: 1 | E22: mol | F22: =D22*B22/1000 -> 0.10617 | G22: kg | H22: ='A. Databases'!H95 -> 0 | I22: =H22*F22 -> 0 | K22: CC1=CC=CC=C1 | L22: 92.14 | M22: MW | N22: 1 | O22: mol | P22: =N22*L22/1000 -> 0.09214 | Q22: kg | R22: ='A. Databases'!H22 -> 0 | S22: =R22*P22 -> 0
A23: Cl2 | B23: 70.9 | C23: MW | D23: 3 | E23: mol | F23: =D23*B23/1000 -> 0.2127 | G23: kg | H23: ='A. Databases'!$H$12 -> 0 | I23: =H23*F23 -> 0 | K23: Cl2 | L23: 70.9 | M23: MW | N23: 1.5 | O23: mol | P23: =N23*L23/1000 -> 0.10635 | Q23: kg | R23: ='A. Databases'!$H$12 -> 0 | S23: =R23*P23 -> 0
A24: - | K24: -
A25: Solvents | B25: molecular weight | C25: Unit | D25: Moles | E25: Unit | F25: Mass Stoich | G25: Unit | H25: GWP kgCO2-eq/kg | I25: GWP kgCO2-eq | K25: Solvents | L25: molecular weight | M25: Unit | N25: Moles | O25: Unit | P25: Mass Stoich | Q25: Unit | R25: GWP kgCO2-eq/kg | S25: GWP kgCO2-eq
A26: - | K26: -
A27: - | K27: -
A28: Yield | B28: 0.95 | K28: Yield | L28: 0.95
A29: Product | B29: molecular weight | C29: Unit | D29: Moles | E29: Unit | F29: Mass Stoich | G29: Unit | H29: GWP kgCO2-eq/kg | I29: GWP kgCO2-eq | K29: Product | L29: molecular weight | M29: Unit | N29: Moles | O29: Unit | P29: Mass Stoich | Q29: Unit | R29: GWP kgCO2-eq/kg | S29: GWP kgCO2-eq
A30: ClC(C1=CC(C(Cl)(Cl)Cl)=CC=C1)(Cl)Cl | B30: 312.82 | C30: MW | D30: 1 | E30: mol | F30: =D30*B30/1000 -> 0.31282 | G30: kg | H30: =I30/F30/B28 -> 0 | I30: =SUM(I22,I23,I26,I27,I28) -> 0 | K30: ClC(C1=CC(C(Cl)(Cl)Cl)=CC=C1)(Cl)Cl | L30: 195.47 | M30: MW | N30: 1 | O30: mol | P30: =N30*L30/1000 -> 0.19547 | Q30: kg | R30: =S30/P30/L28 -> 0 | S30: =SUM(S22,S23,S26,S27,S28) -> 0
A32: Step 2 | K32: Step 2
A34: Reactants | B34: molecular weight | C34: Unit | D34: Moles | E34: Unit | F34: Mass Stoich | G34: Unit | H34: GWP kgCO2-eq/kg | I34: GWP kgCO2-eq | K34: Reactants | L34: molecular weight | M34: Unit | N34: Moles | O34: Unit | P34: Mass Stoich | Q34: Unit | R34: GWP kgCO2-eq/kg | S34: GWP kgCO2-eq
A35: ClC(C1=CC(C(Cl)(Cl)Cl)=CC=C1)(Cl)Cl | B35: 312.82 | C35: MW | D35: 1 | E35: mol | F35: 0.31282 | G35: kg | H35: =H30 -> 0 | I35: =H35*F35 -> 0 | K35: ClC(C1=CC(C(Cl)(Cl)Cl)=CC=C1)(Cl)Cl | L35: 195.47 | M35: MW | N35: 1 | O35: mol | P35: 0.31282 | Q35: kg | R35: =R30 -> 0 | S35: =R35*P35 -> 0
A36: HF | B36: 20.01 | C36: MW | D36: 6 | E36: mol | F36: =D36*B36/1000 -> 0.12006 | G36: kg | H36: ='A. Databases'!$H$96 -> 0 | I36: =H36*F36 -> 0 | K36: HF | L36: 20.01 | M36: MW | N36: 3 | O36: mol | P36: =N36*L36/1000 -> 0.06003 | Q36: kg | R36: ='A. Databases'!$H$96 -> 0 | S36: =R36*P36 -> 0
A38: Solvents | B38: molecular weight | C38: Unit | D38: Moles | E38: Unit | F38: Mass Stoich | G38: Unit | H38: GWP kgCO2-eq/kg | I38: GWP kgCO2-eq | K38: Solvents | L38: molecular weight | M38: Unit | N38: Moles | O38: Unit | P38: Mass Stoich | Q38: Unit | R38: GWP kgCO2-eq/kg | S38: GWP kgCO2-eq
A39: - | K39: -
A40: - | K40: -
A41: Yield | B41: 1 | K41: Yield | L41: 1
A42: Product | B42: molecular weight | C42: Unit | D42: Moles | E42: Unit | F42: Mass Stoich | G42: Unit | H42: GWP kgCO2-eq/kg | I42: GWP kgCO2-eq | K42: Product | L42: molecular weight | M42: Unit | N42: Moles | O42: Unit | P42: Mass Stoich | Q42: Unit | R42: GWP kgCO2-eq/kg | S42: GWP kgCO2-eq
A43: FC(C1=CC(C(F)(F)F)=CC=C1)(F)F | B43: 214.11 | C43: MW | D43: 1 | E43: mol | F43: =B43*D43/1000 -> 0.21411 | H43: =I43/F43/B41 -> 0 | I43: =SUM(I35,I36,I37,I39,I40) -> 0 | K43: FC(C1=CC(C(F)(F)F)=CC=C1)(F)F | L43: 146.11 | M43: MW | N43: 1 | O43: mol | P43: =L43*N43/1000 -> 0.14611 | R43: =S43/P43/L41 -> 0 | S43: =SUM(S35,S36,S37,S39,S40) -> 0
A45: Step 3 | K45: Step 3
A47: Reactants | B47: molecular weight | C47: Unit | D47: Moles | E47: Unit | F47: Mass Stoich | G47: Unit | H47: GWP kgCO2-eq/kg | I47: GWP kgCO2-eq | K47: Reactants | L47: molecular weight | M47: Unit | N47: Moles | O47: Unit | P47: Mass Stoich | Q47: Unit | R47: GWP kgCO2-eq/kg | S47: GWP kgCO2-eq
A48: FC(C1=CC(C(F)(F)F)=CC=C1)(F)F | B48: 214.11 | C48: MW | D48: 1 | E48: mol | F48: 0.21411 | G48: kg | H48: =H43 -> 0 | I48: =H48*F48 -> 0 | K48: FC(C1=CC(C(F)(F)F)=CC=C1)(F)F | L48: 146.11 | M48: MW | N48: 1 | O48: mol | P48: 0.21411 | Q48: kg | R48: =R43 -> 0 | S48: =R48*P48 -> 0
A49: H2SO4 | B49: 98.079 | C49: MW | D49: 1 | E49: mol | F49: =B49*D49/1000 -> 0.098079 | G49: kg | H49: ='A. Databases'!$H$16 -> 0 | I49: =H49*F49 -> 0 | K49: H2SO4 | L49: 98.079 | M49: MW | N49: 1 | O49: mol | P49: =L49*N49/1000 -> 0.098079 | Q49: kg | R49: ='A. Databases'!$H$16 -> 0 | S49: =R49*P49 -> 0
A50: O=C(N1Br)N(Br)C(C)(C)C1=O | B50: 0 | H50: ? | K50: O=C(N1Br)N(Br)C(C)(C)C1=O | L50: 0 | R50: ?
A51: Solvents | B51: molecular weight | C51: Unit | D51: Moles | E51: Unit | F51: Mass Stoich | G51: Unit | H51: GWP kgCO2-eq/kg | I51: GWP kgCO2-eq | K51: Solvents | L51: molecular weight | M51: Unit | N51: Moles | O51: Unit | P51: Mass Stoich | Q51: Unit | R51: GWP kgCO2-eq/kg | S51: GWP kgCO2-eq
...

Sheet B.3. Pd Catalyst
A1: Compound | B1: MW [g/mol] | C1: Unit
A2: (t-Bu)3P-Pd G2 | B2: 512.4 | C2: g/mol
A3: Pd Content | B3: =B5/B6 -> 0.20768931
B4: MW [g/mol] | C4: Unit
A5: Pd | B5: 106.42 | C5: g/mol
A6: (t-Bu)3P-Pd G2 | B6: 512.4 | C6: g/mol
A9: Ligand Calculation
B11: MW [g/mol] | C11: unit | D11: Content on whole catalyst
A12: Tri-tert-butylphosphin | B12: 202.32 | C12: g/mol | D12: =B12/B2 -> 0.39484778
A13: [1,1'-biphenyl]-2-amine | B13: 169.227 | C13: g/mol | D13: =B13/B2 -> 0.33026347
A16: Tri-tert-butylphosphin
A18: Reaction Step | B18: Reactant | C18: MW [g/mol] | D18: LCI | E18: product | F18: MW | G18: LCI | H18: Yield
A19: Cat.1.1 | B19: tert butanol | C19: 74.12 | D19: ='A. Databases'!H120 -> 0 | E19: tert butly chloride | F19: 92.57 | G19: =((C19*D19+C20*D20)/F19)/H19 -> 0 | H19: 0.88
A20: Cat.1.1 | B20: HCl | C20: 36.46 | D20: ='A. Databases'!H79 -> 0
A21: Cat.1.2 | B21: tert butly chloride | C21: 92.57 | D21: =G19 -> 0 | E21: tert butly magnesium chloride | F21: 116.87 | G21: =((C21*D21+C22*D22)/F21)/H21 -> 0 | H21: 1
B22: magnesium | C22: 24.31 | D22: ='A. Databases'!H121 -> 0
A23: Cat 1.3. | B23: tert butly magnesium chloride | C23: 116.87 | D23: =G21 -> 0 | E23: Tri-tert-butylphosphin | F23: 202.32 | G23: =((C23*D23+C24*D24)/F23)/H23 -> 0 | H23: 0.883
B24: PCl3 | C24: 137.32 | D24: ='A. Databases'!H119 -> 0
A26: [1,1'-biphenyl]-2-amine
A27: Reaction Step | B27: Reactant | C27: MW [g/mol] | D27: LCI | E27: Product | F27: MW | G27: LCI | H27: Yield
A28: Cat.2.1 | B28: 2-Nitroaniline | C28: 138.13 | D28: ='A. Databases'!H123 -> 0 | E28: 2-nitro-1,1'-biphenyl | F28: 199.21 | G28: =((C28*D28+C29*D29+C30*D30)/F28)/H28 -> 0 | H28: 0.58
B29: Benzene | C29: 78.1 | D29: ='A. Databases'!H124 -> 0
B30: Sodium Nitrite | C30: 68.9953 | D30: ='A. Databases'!H122 -> 0
A31: Cat.2.2 | B31: 2-nitro-1,1'-biphenyl | C31: 199.21 | D31: =G28 -> 0 | E31: [1,1'-biphenyl]-2-amine | F31: 169.23 | G31: =(C31*D31+C32*D32)/F31 -> 0 | H31: 1
B32: H2 | C32: 2 | D32: ='A. Databases'!H102 -> 0
A37: 1kg Catalyst
B38: Unit | C38: Relative Amount | D38: GWP per FU kgco2eq/kg | E38: GWP if share Accounted kgco2eq/kg
A39: Pd | B39: Share in % | C39: =B3 -> 0.20768931 | D39: ='A. Databases'!H30 -> 0 | E39: =D39*C39 -> 0
A40: Tri-tert-butylphosphin | B40: Share in % | C40: =D12 -> 0.39484778 | D40: =G23 -> 0 | E40: =D40*C40 -> 0
A41: [1,1'-biphenyl]-2-amine | B41: Share in % | C41: =D13 -> 0.33026347 | D41: =G31 -> 0 | E41: =D41*C41 -> 0
D43: Number of cycles | E43: Total Sum for 1kg of Catalyst (kgCO2eq/kg) | F43: w/recovery rate kgCO2/kg
D44: =B56 -> 1 | E44: =SUM(E39:E41) -> 0 | F44: =E44/D44 -> 0
A49: Recovery Rate calculation | B49: Equation referenced in text
A51: Equation
A53: R_threshold | B53: 0.5
A54: r = (1-recovery rate) | B54: =(1-D54) -> 0.5 | C54: Recovery rate | D54: =Macro!D15 -> 0.5
A56: Number of cycles n | B56: =LN(B53)/LN(1-B54) -> 1

Sheet B.4. Precursors
A1: Merck Precursor
A3: Reaction Step | B3: Precursors | C3: MW [g/mol] | D3: LCI | E3: Products | F3: MW [g/mol] | G3: LCI | H3: Reagencies | J3: LCI | K3: Solvents | L3: LCI | M3: Reaction Energy | O3: Yield | P3: Estimated LCI to this stage | Q3: Literature
A4: P.1 | B4: ClC1=CC=CC=C1N(=O)=O | C4: 157.55 | D4: ='A. Databases'!H11 -> 0 | E4: FC1=C(C=CC=C1)N(=O)=O | F4: 141.1 | G4: =((D4*C4/1000)*(1/O4)+J4+L4*(C4/1000))/(F4/1000) -> 0 | H4: KF | K4: dimethyl sulfoxide | L4: ='A. Databases'!H4 -> 0 | M4: 200 C, 3h | O4: 0.901
A5: P.2 | B5: FC1=C(C=CC=C1)N(=O)=O | C5: 141.1 | D5: =G4 -> 0 | E5: NC1=C(F)C=CC=C1 | F5: 111.12 | G5: =((C5*D5/1000)*(1/O5)+(J5+L5)*(C5/1000))/(F5/1000) -> 0 | H5: ammonium hydroxide, hydrogen | J5: ='A. Databases'!H20+'A. Databases'!H13 -> 0 | K5: methanol, water | L5: ='A. Databases'!H28 -> 0 | M5: 50 C, 8h | O5: 0.996
A6: P.3 | B6: NC1=C(F)C=CC=C1 | C6: 111.12 | D6: =G5 -> 0 | E6: NC1=C(F)C=CC=C1Br | F6: 188.96 | G6: =((C6*D6/1000)+(I6*J6/1000)+(I7*J7/1000)+(I8*J8/1000)+(I9*J9/1000)+(I10*J10/1000))/(F6/1000)/O6 -> 0 | H6: acetic acid | I6: 60.052 | J6: ='A. Databases'!H125 -> 0 | O6: 0.44
H7: Ammonia | I7: 17.031 | J7: ='A. Databases'!H13 -> 0
H8: chloro sulfonic acid | I8: 116.52 | J8: ='A. Databases'!H126 -> 0
H9: HBr (simplified as Br2) | I9: 80.91 | J9: ='A. Databases'!H27 -> 0
H10: surlfurc acid | I10: 98.08 | J10: ='A. Databases'!H16 -> 0 | K10: Assumtion 1kg of solvents per kg of reactant in each step
A13: Carreira Precursor
A15: Reaction Step | B15: Precursors | C15: MW [g/mol] | D15: LCI | E15: Products | F15: MW [g/mol] | G15: LCI | H15: Reagencies | I15: MW | J15: LCI | K15: Solvents | L15: LCI | M15: Reaction Energy | O15: Yield | P15: Estimated GWP to this stage | Q15: Literature
A16: P.1 | B16: ClC1=CC=CC=C1N(=O)=O | C16: 157.55 | D16: ='A. Databases'!H11 -> 0 | E16: FC1=C(C=CC=C1)N(=O)=O | F16: 141.1 | G16: =((C16*D16/1000)/O16+L16*(C16/1000))/(F16/1000) -> 0 | H16: KF | K16: dimethly sulfoxide | L16: ='A. Databases'!H4 -> 0 | M16: 200 C, 3h | O16: 0.901
A17: P.2 | B17: FC1=C(C=CC=C1)N(=O)=O | C17: 141.1 | D17: =G16 -> 0 | E17: NC1=C(F)C=CC=C1 | F17: 111.12 | G17: =((C17*D17/1000)/O17+(J17+L17)*(C17/1000))/(F17/1000) -> 0 | H17: ammonia hydroxide, hydrogen | J17: ='A. Databases'!H20+'A. Databases'!H13 -> 0 | K17: MeOH | L17: ='A. Databases'!H33 -> 0 | M17: 50 C, 8h | O17: 0.996
A18: P.3 | B18: NC1=C(F)C=CC=C1 | C18: 111.12 | D18: =G17 -> 0 | E18: FC1=C2NC(=O)C(=O)C2=CC=C1 | F18: 165.12 | G18: =((C18*D18/1000)/O18+L18*(C18/1000))/(F18/1000) -> 0 | O18: 0.57
A19: P.4 | B19: FC1=C2NC(=O)C(=O)C2=CC=C1 | C19: 165.12 | D19: =G18 -> 0 | E19: NC1=C(C=CC=C1F)C(O)=O | F19: 155.13 | G19: =((C19*D19/1000)/O19+(J19+L19)*(C19/1000))/(F19/1000) -> 0 | H19: dihydrogen peroxide, NaOH | J19: ='A. Databases'!H14+'A. Databases'!H20 -> 0 | K19: H2O | L19: ='A. Databases'!H38 -> 0 | M19: RT, 2.25 h | O19: 0.96
A20: old | J20: mCPBA
A21: Reaction Step | B21: Precursors | C21: Equiv | D21: LCI | E21: Products | F21: Equiv | G21: LCI | H21: Reagencies | I21: Equiv | J21: LCI | K21: Solvents | L21: LCI | M21: Reaction Energy | O21: Yield | P21: Estimated GWP to this stage | Q21: Literature
A22: P.1 | B22: CC1=CC=CC=C1 | C22: 1 | E22: ClC1=CC=C(C)C=C1>> | F22: 1 | H22: Cl2 Gas | I22: 1 | J22: ='A. Databases'!H12 -> 0 | O22: 0.725
A23: P.2 | B23: ClC1=CC=C(C)C=C1>> | C23: 1 | E23: NC1=CC=CC(C)=C1 | F23: 1 | H23: NH3 | I23: 1 | J23: ='A. Databases'!H13 -> 0 | O23: 0.87
A24: P.3 | B24: NC1=CC=CC(C)=C1 | C24: 1 | D24: ='A. Databases'!H91 -> 0 | E24: CC1=CC([N+]([O-])=O)=CC=C1 | F24: 1 | G24: =(D24+J24)/O24 -> 0 | H24: H2O2 | I24: 1 | J24: ='A. Databases'!H14 -> 0 | O24: 0.95
A25: P.4 | B25: CC1=CC([N+]([O-])=O)=CC=C1 | C25: 1 | D25: =G24 -> 0 | E25: ClC1=CC=CC(C(Cl)=O)=C1 | F25: 1 | G25: =(D25+J25)/O25 -> 0 | H25: DMF, Cl2 Gas | I25: 1 | J25: ='A. Databases'!H12 -> 0 | O25: 0.923
A26: P.5 | B26: ClC1=CC=CC(C(Cl)=O)=C1 | C26: 1 | D26: =G25 -> 0 | E26: ClC1=CC=CC(C(O)=O)=C1 | F26: 1 | G26: =(D26+J26)/O26 -> 0 | H26: H2O | I26: 1 | J26: ='A. Databases'!H38 -> 0 | O26: 1
A27: P.6 | B27: ClC1=CC=CC(C(O)=O)=C1 | C27: 1 | D27: =G26 -> 0 | E27: ClC1=CC=CC(C(Cl)=O)=C1 | F27: 1 | G27: =(D27+J27)/O27 -> 0 | H27: SOCl2 | I27: 1 | J27: ='A. Databases'!H67 -> 0 | O27: 1
A28: P.7 | B28: ClC1=CC=CC(C(Cl)=O)=C1 | C28: 1 | D28: =G27 -> 0 | E28: ClC1=CC=CC(C(OO)=O)=C1 | F28: 1 | G28: =(D28+J28)/O28 -> 0 | H28: H2O2, MgSO4, H2SO4 | I28: 1 | J28: ='A. Databases'!H14+'A. Databases'!H15+'A. Databases'!H16 -> 0 | O28: 1
J31: DMAP
A32: Reaction Step | B32: Precursors | C32: Equiv | D32: LCI | E32: Products | F32: Equiv | G32: LCI | H32: Reagencies | I32: Equiv | J32: LCI | K32: Solvents | L32: LCI | M32: Reaction Energy | O32: Yield | P32: Estimated GWP to this stage | Q32: Literature
A33: P.1 | B33: C1=CC=CN=C1 | C33: 2 | D33: ='A. Databases'!H71 -> 0 | E33: [N+]1(C2=CC=NC=C2)=CC=CC=C1 | F33: 1 | G33: =2*D33+J33 -> 0 | H33: Cl2 | I33: 1 | J33: ='A. Databases'!H12 -> 0 | O33: 1
E34: C1=CC=C[NH+]=C1.[Cl-] | G34: =1*D33+J33 -> 0 | I34: 1
A35: P.2 | B35: [N+]1(C2=CC=NC=C2)=CC=CC=C1 | C35: 1 | D35: =G33 -> 0 | E35: CN(C)C1=CC=NC=C1 (DMAP) | F35: 0.333 | G35: =(D35+D36+J35)/3 -> 0 | H35: me2N | I35: 1 | J35: ='A. Databases'!H72 -> 0 | O35: 1
B36: C1=CC=C[NH+]=C1.[Cl-] | C36: 1 | D36: =G34 -> 0 | E36: C1=CC=C[NH+]=C1.[Cl-] (2x) | F36: 0.666 | G36: =((D35+D36+J35)/3)*2 -> 0 | I36: 1
J40: TFAA
A41: Reaction Step | B41: Precursors | C41: MW [g/mol] | D41: LCI | E41: Products | F41: MW [g/mol] | G41: LCI | H41: Reagencies | I41: MW | J41: LCI | K41: Solvents | L41: LCI | M41: Reaction Energy | O41: Yield | P41: Estimated GWP to this stage | Q41: Literature
A42: P.1 | B42: OC(C(F)(F)F)=O | C42: 114.02 | D42: ='A. Databases'!H17 -> 0 | E42: O=C(OC(C(F)(F)F)=O)C(F)(F)F | F42: 210.03 | G42: =((2*C42*D42+I42*J42+I43*J43)/F42)/O42 -> 0 | H42: H2SO4 | I42: 98.08 | J42: ='A. Databases'!H16 -> 0 | M42: 130 C | N42: 10 h | O42: 0.99
H43: SO3 | I43: 80.06 | J43: ='A. Databases'!H48 -> 0
J46: OTBS
A47: Reaction Step | B47: Precursors | C47: Equiv | D47: LCI | E47: Products | F47: Equiv | G47: LCI | H47: Reagencies | I47: Equiv | J47: LCI | K47: Solvents | L47: LCI | M47: Reaction Energy | O47: Yield | P47: Estimated GWP to this stage | Q47: Literature
A48: P.1 | B48: CC(OC)=O | C48: 1 | D48: ='A. Databases'!H93 -> 0 | E48: C=C(O[Si](C)(C)C(C)(C)C)OC | F48: 1 | G48: =D48+L48 -> 0 | H48: nBuLi | I48: 1 | J48: no infromation | K48: THF | L48: ='A. Databases'!H36 -> 0 | M48: minus 78 to RT | O48: no infromation
H49: diisoproylamine, tert-butyl-dimethyl-silyl chloride, N.N'-Dimethylpropyleneurea | J49: no infromation
J52: 2-isothiocyanato-1-methoxy-4-(trifluoromethyl)benzene
A53: Reaction Step | B53: Precursors | C53: MW [g/mol] | D53: LCI | E53: Products | F53: MW [g/mol] | G53: LCI | H53: Reagencies | I53: MW | J53: LCI | K53: Solvents | L53: LCI | M53: Reaction Energy | O53: Yield | P53: Estimated GWP to this stage | Q53: Literature
...
